#usda 1.0
(
    defaultPrim = "Robot"
    metersPerUnit = 1
    upAxis = "Z"
)

# This is an example of the USD output structure generated by Phidias.
# It demonstrates the physics schema organization for NVIDIA Isaac Sim.

def Xform "Robot" (
    prepend apiSchemas = ["PhysicsArticulationRootAPI"]
)
{
    # Physics Scene - defines simulation parameters
    def PhysicsScene "PhysicsScene"
    {
        vector3f physics:gravityDirection = (0, 0, -1)
        float physics:gravityMagnitude = 9.81
    }

    # Base link - fixed in world, root of articulation
    def Xform "base" (
        prepend apiSchemas = ["PhysicsRigidBodyAPI", "PhysicsMassAPI"]
    )
    {
        bool physics:kinematicEnabled = true
        float physics:density = 1000
        
        def Mesh "mesh" (
            prepend apiSchemas = ["PhysicsCollisionAPI", "PhysicsMeshCollisionAPI"]
        )
        {
            # Mesh geometry would be here
            point3f[] points = [(0, 0, 0), (1, 0, 0), (1, 1, 0), (0, 1, 0)]
            int[] faceVertexCounts = [4]
            int[] faceVertexIndices = [0, 1, 2, 3]
            uniform token subdivisionScheme = "none"
        }
    }

    # Link 1 - dynamic rigid body
    def Xform "link_1" (
        prepend apiSchemas = ["PhysicsRigidBodyAPI", "PhysicsMassAPI"]
    )
    {
        float physics:density = 1000
        
        def Mesh "mesh" (
            prepend apiSchemas = ["PhysicsCollisionAPI", "PhysicsMeshCollisionAPI"]
        )
        {
            point3f[] points = [(0, 0, 0), (0.5, 0, 0), (0.5, 0.1, 0), (0, 0.1, 0)]
            int[] faceVertexCounts = [4]
            int[] faceVertexIndices = [0, 1, 2, 3]
            uniform token subdivisionScheme = "none"
        }
    }

    # Link 2 - dynamic rigid body
    def Xform "link_2" (
        prepend apiSchemas = ["PhysicsRigidBodyAPI", "PhysicsMassAPI"]
    )
    {
        float physics:density = 1000
        
        def Mesh "mesh" (
            prepend apiSchemas = ["PhysicsCollisionAPI", "PhysicsMeshCollisionAPI"]
        )
        {
            point3f[] points = [(0, 0, 0), (0.3, 0, 0), (0.3, 0.1, 0), (0, 0.1, 0)]
            int[] faceVertexCounts = [4]
            int[] faceVertexIndices = [0, 1, 2, 3]
            uniform token subdivisionScheme = "none"
        }
    }

    # Gripper - tool/end effector
    def Xform "gripper" (
        prepend apiSchemas = ["PhysicsRigidBodyAPI", "PhysicsMassAPI"]
    )
    {
        float physics:density = 1000
        
        def Mesh "mesh" (
            prepend apiSchemas = ["PhysicsCollisionAPI", "PhysicsMeshCollisionAPI"]
        )
        {
            point3f[] points = [(0, 0, 0), (0.1, 0, 0), (0.1, 0.05, 0), (0, 0.05, 0)]
            int[] faceVertexCounts = [4]
            int[] faceVertexIndices = [0, 1, 2, 3]
            uniform token subdivisionScheme = "none"
        }
    }

    # Joints container
    def Xform "Joints"
    {
        # Revolute joint - base to link_1
        def PhysicsRevoluteJoint "joint_1"
        {
            rel physics:body0 = </Robot/base>
            rel physics:body1 = </Robot/link_1>
            uniform token physics:axis = "Z"
            float physics:lowerLimit = -180
            float physics:upperLimit = 180
            point3f physics:localPos0 = (0, 0, 0)
            point3f physics:localPos1 = (0, 0, 0)
            quatf physics:localRot0 = (1, 0, 0, 0)
            quatf physics:localRot1 = (1, 0, 0, 0)
        }

        # Revolute joint - link_1 to link_2
        def PhysicsRevoluteJoint "joint_2"
        {
            rel physics:body0 = </Robot/link_1>
            rel physics:body1 = </Robot/link_2>
            uniform token physics:axis = "Z"
            float physics:lowerLimit = -90
            float physics:upperLimit = 90
            point3f physics:localPos0 = (0, 0, 0)
            point3f physics:localPos1 = (0, 0, 0)
            quatf physics:localRot0 = (1, 0, 0, 0)
            quatf physics:localRot1 = (1, 0, 0, 0)
        }

        # Prismatic joint - link_2 to gripper
        def PhysicsPrismaticJoint "joint_3"
        {
            rel physics:body0 = </Robot/link_2>
            rel physics:body1 = </Robot/gripper>
            uniform token physics:axis = "X"
            float physics:lowerLimit = 0
            float physics:upperLimit = 0.1
            point3f physics:localPos0 = (0, 0, 0)
            point3f physics:localPos1 = (0, 0, 0)
            quatf physics:localRot0 = (1, 0, 0, 0)
            quatf physics:localRot1 = (1, 0, 0, 0)
        }
    }
}
